<?xml version="1.0" ?>
<!-- =================================================================================== -->
<!-- |    This document was autogenerated by xacro from iiwa14_rs_scanner_v1.urdf.xacro | -->
<!-- |    EDITING THIS FILE BY HAND IS NOT RECOMMENDED                                 | -->
<!-- =================================================================================== -->
<!-- Here we define the robot, we named it "iiwa14_rs_scanner_v1, realsense camera with pointy tool" -->
<robot name="iiwa14_rs_scanner_v1">
  <material name="Black">
    <color rgba="0.0 0.0 0.0 1.0"/>
  </material>
  <material name="Blue">
    <color rgba="0.0 0.0 0.8 1.0"/>
  </material>
  <material name="Green">
    <color rgba="0.0 0.8 0.0 1.0"/>
  </material>
  <material name="Grey">
    <color rgba="0.4 0.4 0.4 1.0"/>
  </material>
  <material name="Orange">
    <color rgba="1.0 0.4235294117647059 0.0392156862745098 1.0"/>
  </material>
  <material name="Brown">
    <color rgba="0.8705882352941177 0.8117647058823529 0.7647058823529411 1.0"/>
  </material>
  <material name="Red">
    <color rgba="0.8 0.0 0.0 1.0"/>
  </material>
  <material name="White">
    <color rgba="1.0 1.0 1.0 1.0"/>
  </material>
  <!--  Define the origin of your 3D space
  Here we define a box lying at 0,0,0 with some dimensions, in reality our robot is place on top of a metal cart with those dimensions.
  This will include the cart in the scene and avoid the robot to hit it when using MoveIt! 
  If you don't want to have that you can define a basic world link (see commented lines)
  -->
  <link name="world"/>
  <!--link name="world">
    <visual>
      <origin xyz="0 0 0.42" rpy="0 0 0"/>
      <geometry>
	<box size="0.68 0.605 0.84"/>
      </geometry>
    </visual>
    <collision>
      <origin xyz="0 0 0.42" rpy="0 0 0"/>
      <geometry>
	<box size="0.68 0.605 0.84"/>
      </geometry>
    </collision>
  </link-->
  <!-- <gazebo reference="world">
    <static>true</static>
  </gazebo> -->
  <!--joint between {parent} and link_0-->
  <joint name="world_iiwa_joint" type="fixed">
    <origin rpy="0 0 0" xyz="0 0 0"/>
    <parent link="world"/>
    <child link="iiwa_link_0"/>
  </joint>
  <link name="iiwa_link_0">
    <inertial>
      <origin rpy="0 0 0" xyz="-0.1 0 0.07"/>
      <mass value="5"/>
      <inertia ixx="0.05" ixy="0" ixz="0" iyy="0.06" iyz="0" izz="0.03"/>
    </inertial>
    <visual>
      <origin rpy="0 0 0" xyz="0 0 0"/>
      <geometry>
        <mesh filename="meshes/iiwa14/visual/link_0.stl"/>
      </geometry>
      <material name="Grey"/>
    </visual>
    <collision>
      <origin rpy="0 0 0" xyz="0 0 0"/>
      <geometry>
        <mesh filename="meshes/iiwa14/visual/link_0.stl"/>
      </geometry>
      <material name="Grey"/>
    </collision>
    <self_collision_checking>
      <origin rpy="0 0 0" xyz="0 0 0"/>
      <geometry>
        <capsule length="0.25" radius="0.15"/>
      </geometry>
    </self_collision_checking>
  </link>
  <!-- joint between link_0 and link_1 -->
  <joint name="iiwa_joint_1" type="revolute">
    <parent link="iiwa_link_0"/>
    <child link="iiwa_link_1"/>
    <origin rpy="0 0 0" xyz="0 0 0.1575"/>
    <axis xyz="0 0 1"/>
    <limit effort="320" lower="-2.9670597283903604" upper="2.9670597283903604" velocity="1.4835298641951802"/>
    <safety_controller k_position="100" k_velocity="10" soft_lower_limit="-2.8187067419708423" soft_upper_limit="2.8187067419708423"/>
    <dynamics damping="0.5"/>
  </joint>
  <link name="iiwa_link_1">
    <inertial>
      <origin rpy="0 0 0" xyz="0 -0.03 0.12"/>
      <mass value="4"/>
      <inertia ixx="0.1" ixy="0" ixz="0" iyy="0.09" iyz="0" izz="0.02"/>
    </inertial>
    <visual>
      <origin rpy="0 0 0" xyz="0 0 0"/>
      <geometry>
        <mesh filename="meshes/iiwa14/visual/link_1.stl"/>
      </geometry>
      <material name="White"/>
    </visual>
    <collision>
      <origin rpy="0 0 0" xyz="0 0 0"/>
      <geometry>
        <mesh filename="meshes/iiwa14/visual/link_1.stl"/>
      </geometry>
      <material name="White"/>
    </collision>
  </link>
  <!-- joint between link_1 and link_2 -->
  <joint name="iiwa_joint_2" type="revolute">
    <parent link="iiwa_link_1"/>
    <child link="iiwa_link_2"/>
    <origin rpy="1.5707963267948966   0 3.141592653589793" xyz="0 0 0.2025"/>
    <axis xyz="0 0 1"/>
    <limit effort="320" lower="-2.0943951023931953" upper="2.0943951023931953" velocity="1.4835298641951802"/>
    <safety_controller k_position="100" k_velocity="10" soft_lower_limit="-1.9896753472735356" soft_upper_limit="1.9896753472735356"/>
    <dynamics damping="0.5"/>
  </joint>
  <link name="iiwa_link_2">
    <inertial>
      <origin rpy="0 0 0" xyz="0.0003 0.059 0.042"/>
      <mass value="4"/>
      <inertia ixx="0.05" ixy="0" ixz="0" iyy="0.018" iyz="0" izz="0.044"/>
    </inertial>
    <visual>
      <origin rpy="0 0 0" xyz="0 0 0"/>
      <geometry>
        <mesh filename="meshes/iiwa14/visual/link_2.stl"/>
      </geometry>
      <material name="White"/>
    </visual>
    <collision>
      <origin rpy="0 0 0" xyz="0 0 0"/>
      <geometry>
        <mesh filename="meshes/iiwa14/visual/link_2.stl"/>
      </geometry>
      <material name="White"/>
    </collision>
  </link>
  <!-- joint between link_2 and link_3 -->
  <joint name="iiwa_joint_3" type="revolute">
    <parent link="iiwa_link_2"/>
    <child link="iiwa_link_3"/>
    <origin rpy="1.5707963267948966 0 3.141592653589793" xyz="0 0.2045 0"/>
    <axis xyz="0 0 1"/>
    <limit effort="176" lower="-2.9670597283903604" upper="2.9670597283903604" velocity="1.7453292519943295"/>
    <safety_controller k_position="100" k_velocity="10" soft_lower_limit="-2.8187067419708423" soft_upper_limit="2.8187067419708423"/>
    <dynamics damping="0.5"/>
  </joint>
  <link name="iiwa_link_3">
    <inertial>
      <origin rpy="0 0 0" xyz="0 0.03 0.13"/>
      <mass value="3"/>
      <inertia ixx="0.08" ixy="0" ixz="0" iyy="0.075" iyz="0" izz="0.01"/>
    </inertial>
    <visual>
      <origin rpy="0 0 0" xyz="0 0 0"/>
      <geometry>
        <mesh filename="meshes/iiwa14/visual/link_3.stl"/>
      </geometry>
      <material name="White"/>
    </visual>
    <collision>
      <origin rpy="0 0 0" xyz="0 0 0"/>
      <geometry>
        <mesh filename="meshes/iiwa14/visual/link_3.stl"/>
      </geometry>
      <material name="White"/>
    </collision>
  </link>
  <!-- joint between link_3 and link_4 -->
  <joint name="iiwa_joint_4" type="revolute">
    <parent link="iiwa_link_3"/>
    <child link="iiwa_link_4"/>
    <origin rpy="1.5707963267948966 0 0" xyz="0 0 0.2155"/>
    <axis xyz="0 0 1"/>
    <limit effort="176" lower="-2.0943951023931953" upper="2.0943951023931953" velocity="1.3089969389957472"/>
    <safety_controller k_position="100" k_velocity="10" soft_lower_limit="-1.9896753472735356" soft_upper_limit="1.9896753472735356"/>
    <dynamics damping="0.5"/>
  </joint>
  <link name="iiwa_link_4">
    <inertial>
      <origin rpy="0 0 0" xyz="0 0.067 0.034"/>
      <mass value="2.7"/>
      <inertia ixx="0.03" ixy="0" ixz="0" iyy="0.01" iyz="0" izz="0.029"/>
    </inertial>
    <visual>
      <origin rpy="0 0 0" xyz="0 0 0"/>
      <geometry>
        <mesh filename="meshes/iiwa14/visual/link_4.stl"/>
      </geometry>
      <material name="White"/>
    </visual>
    <collision>
      <origin rpy="0 0 0" xyz="0 0 0"/>
      <geometry>
        <mesh filename="meshes/iiwa14/visual/link_4.stl"/>
      </geometry>
      <material name="White"/>
    </collision>
  </link>
  <!-- joint between link_4 and link_5 -->
  <joint name="iiwa_joint_5" type="revolute">
    <parent link="iiwa_link_4"/>
    <child link="iiwa_link_5"/>
    <origin rpy="-1.5707963267948966 3.141592653589793 0" xyz="0 0.1845 0"/>
    <axis xyz="0 0 1"/>
    <limit effort="110" lower="-2.9670597283903604" upper="2.9670597283903604" velocity="2.2689280275926285"/>
    <safety_controller k_position="100" k_velocity="10" soft_lower_limit="-2.8187067419708423" soft_upper_limit="2.8187067419708423"/>
    <dynamics damping="0.5"/>
  </joint>
  <link name="iiwa_link_5">
    <inertial>
      <origin rpy="0 0 0" xyz="0.0001 0.021 0.076"/>
      <mass value="1.7"/>
      <inertia ixx="0.02" ixy="0" ixz="0" iyy="0.018" iyz="0" izz="0.005"/>
    </inertial>
    <visual>
      <origin rpy="0 0 0" xyz="0 0 0"/>
      <geometry>
        <mesh filename="meshes/iiwa14/visual/link_5.stl"/>
      </geometry>
      <material name="White"/>
    </visual>
    <collision>
      <origin rpy="0 0 0" xyz="0 0 0"/>
      <geometry>
        <mesh filename="meshes/iiwa14/visual/link_5.stl"/>
      </geometry>
      <material name="White"/>
    </collision>
  </link>
  <!-- joint between link_5 and link_6 -->
  <joint name="iiwa_joint_6" type="revolute">
    <parent link="iiwa_link_5"/>
    <child link="iiwa_link_6"/>
    <origin rpy="1.5707963267948966 0 0" xyz="0 0 0.2155"/>
    <axis xyz="0 0 1"/>
    <limit effort="40" lower="-2.0943951023931953" upper="2.0943951023931953" velocity="2.356194490192345"/>
    <safety_controller k_position="100" k_velocity="10" soft_lower_limit="-1.9896753472735356" soft_upper_limit="1.9896753472735356"/>
    <dynamics damping="0.5"/>
  </joint>
  <link name="iiwa_link_6">
    <inertial>
      <origin rpy="0 0 0" xyz="0 0.0006 0.0004"/>
      <mass value="1.8"/>
      <inertia ixx="0.005" ixy="0" ixz="0" iyy="0.0036" iyz="0" izz="0.0047"/>
    </inertial>
    <visual>
      <origin rpy="0 0 0" xyz="0 0 0"/>
      <geometry>
        <mesh filename="meshes/iiwa14/visual/link_6.stl"/>
      </geometry>
      <material name="White"/>
    </visual>
    <collision>
      <origin rpy="0 0 0" xyz="0 0 0"/>
      <geometry>
        <mesh filename="meshes/iiwa14/visual/link_6.stl"/>
      </geometry>
      <material name="White"/>
    </collision>
  </link>
  <!-- joint between link_6 and link_7 -->
  <joint name="iiwa_joint_7" type="revolute">
    <parent link="iiwa_link_6"/>
    <child link="iiwa_link_7"/>
    <origin rpy="-1.5707963267948966 3.141592653589793 0" xyz="0 0.081 0"/>
    <axis xyz="0 0 1"/>
    <limit effort="40" lower="-3.0543261909900763" upper="3.0543261909900763" velocity="2.356194490192345"/>
    <safety_controller k_position="100" k_velocity="10" soft_lower_limit="-2.901609881440573" soft_upper_limit="2.901609881440573"/>
    <dynamics damping="0.5"/>
  </joint>
  <link name="iiwa_link_7">
    <inertial>
      <origin rpy="0 0 0" xyz="0 0 0.02"/>
      <mass value="0.3"/>
      <inertia ixx="0.001" ixy="0" ixz="0" iyy="0.001" iyz="0" izz="0.001"/>
    </inertial>
    <visual>
      <origin rpy="0 0 0" xyz="0 0 0"/>
      <geometry>
        <mesh filename="meshes/iiwa14/visual/link_7.stl"/>
      </geometry>
      <material name="Grey"/>
    </visual>
    <collision>
      <origin rpy="0 0 0" xyz="0 0 0"/>
      <geometry>
        <mesh filename="meshes/iiwa14/visual/link_7.stl"/>
      </geometry>
      <material name="Grey"/>
    </collision>
  </link>
  <joint name="iiwa_joint_ee" type="fixed">
    <parent link="iiwa_link_7"/>
    <child link="iiwa_link_ee"/>
    <origin rpy="0 0 0" xyz="0 0 0.045"/>
  </joint>
  <link name="iiwa_link_ee">
    <inertial>
      <origin rpy="0 0 0" xyz="0 0 0"/>
      <mass value="1e-6"/>
      <inertia ixx="1" ixy="0" ixz="0" iyy="1" iyz="0" izz="1"/>
    </inertial>
  </link>
  <!--property name="tool_joint_offset" value="0.00 0.00 0.00" /-->
  <!--property name="tool_link_offset" value="0.00 0.00 0.10" /-->
  <!--  Here we define a dummy joint between the tip of the iiwa14 and the base of the tool. 
  There is no offset between the two, that means the tool is attached at the robot flange. -->
  <joint name="tool_joint" type="fixed">
    <parent link="iiwa_link_ee"/>
    <child link="tool_link"/>
    <origin rpy="0 0 0" xyz="0.0 0.0 0.0"/>
    <!-- <origin xyz="0.0 0.0 0.0" rpy="0 0 0" /> -->
  </joint>
  <!-- Here we define the geometry of the tool. We designed the tool ourselves, so we have a mesh file that represents it.   
  Else, one can define it using a geometric representation that approximate it, like a cylinder (see commented lines) -->
  <link name="tool_link">
    <visual>
      <!-- <origin xyz="-0.120 0.038 0" rpy="0 0 0"/> -->
      <origin rpy="0 0 -1.57" xyz="-0.12 0.04 0"/>
      <geometry>
        <!-- <mesh filename="package://iiwa_description/meshes/tools/visual/rscamera_tool.STL"/> -->
        <mesh filename="meshes/tools/visual/Scanner_mount_assem_prt.STL"/>
        <!-- <cylinder length="0.1275" radius="0.020"/> -->
      </geometry>
      <material name="Grey"/>
    </visual>
    <collision>
      <!-- <origin xyz="-0.120 0.038 0" rpy="0 0 0"/> -->
      <origin rpy="0 0 -1.57" xyz="-0.12 0.04 0"/>
      <geometry>
        <!-- <mesh filename="package://iiwa_description/meshes/tools/collision/rscamera_tool.STL"/> -->
        <mesh filename="meshes/tools/visual/Scanner_mount_assem_prt.STL"/>
        <!-- <cylinder length="0.1275" radius="0.020"/> -->
      </geometry>
      <material name="Grey"/>
    </collision>
  </link>
  <!--  Here we define another dummy joint. It is placed at the end of the tool, so we can then attach a frame at its TCP for control -->
  <joint name="tool_tip_joint" type="fixed">
    <parent link="tool_link"/>
    <child link="tool_link_ee"/>
    <!-- <origin xyz="0.03 0.08 0.19305" rpy="0 0 0" />   -->
    <origin rpy="0 0 0" xyz="0.0 0.0 0.1898"/>
  </joint>
  <!--  The TCP frame is here defined -->
  <link name="tool_link_ee"/>
</robot>

